Workbook

Sheet Activities - Engineering
A1: Activity ID | B1: Activity Name | C1: Phase | D1: Cost Category | E1: Period | F1: Baseline Start | G1: Baseline Finish | H1: Forecast Start | I1: Forecast Finish | J1: Actual Start | K1: Actual Finish | L1: % Complete | M1: Status | N1: Variance (Days) | O1: Root Cause | P1: Impact | Q1: Budget Cost (AED) | R1: Actual Cost (AED) | S1: Forecast Cost (AED) | T1: Planned Hours | U1: Actual Hours | V1: Planned Output | W1: Actual Output | X1: Output Unit | Y1: Productivity Index
A2: ENG-01 | B2: Site Survey & Soil Investigation | C2: Engineering | D2: Engineering & Design Fees | E2: P1 | F2: 45323 | G2: 45332 | H2: 45323 | I2: 45331 | J2: 45323 | K2: 45331 | L2: 1 | M2: =IF(L2=1,IF(K2>G2,"Delayed","Completed"),IF(L2=0,"Not Started",IF(I2>G2,"Delayed","In Progress"))) -> Completed | N2: =I2-G2 -> -1 | O2: - | P2: None | Q2: 20000 | R2: 20000 | S2: 20000 | Y2: =IF(OR(T2="",U2=""),"",IFERROR((W2/U2)/(V2/T2),""))
A3: ENG-02 | B3: Architectural Drawings - IFC | C3: Engineering | D3: Engineering & Design Fees | E3: P1 | F3: 45327 | G3: 45347 | H3: 45328 | I3: 45353 | J3: 45328 | K3: 45353 | L3: 1 | M3: =IF(L3=1,IF(K3>G3,"Delayed","Completed"),IF(L3=0,"Not Started",IF(I3>G3,"Delayed","In Progress"))) -> Delayed | N3: =I3-G3 -> 6 | O3: Client review delays | P3: Low | Q3: 35000 | R3: 35000 | S3: 35000 | Y3: =IF(OR(T3="",U3=""),"",IFERROR((W3/U3)/(V3/T3),""))
A4: ENG-03 | B4: Structural Design & Calculations | C4: Engineering | D4: Engineering & Design Fees | E4: P2 | F4: 45332 | G4: 45352 | H4: 45333 | I4: 45355 | J4: 45333 | K4: 45355 | L4: 1 | M4: =IF(L4=1,IF(K4>G4,"Delayed","Completed"),IF(L4=0,"Not Started",IF(I4>G4,"Delayed","In Progress"))) -> Delayed | N4: =I4-G4 -> 3 | O4: Late input from geotech report | P4: Medium | Q4: 40000 | R4: 40000 | S4: 40000 | Y4: =IF(OR(T4="",U4=""),"",IFERROR((W4/U4)/(V4/T4),""))
A5: ENG-04 | B5: MEP Coordination Drawings | C5: Engineering | D5: MEP Works | E5: P2 | F5: 45337 | G5: 45361 | H5: 45340 | I5: 45366 | J5: 45340 | K5: 45366 | L5: 1 | M5: =IF(L5=1,IF(K5>G5,"Delayed","Completed"),IF(L5=0,"Not Started",IF(I5>G5,"Delayed","In Progress"))) -> Delayed | N5: =I5-G5 -> 5 | O5: Design clashes requiring rework | P5: Medium | Q5: 190000 | R5: 187500 | S5: 190000 | Y5: =IF(OR(T5="",U5=""),"",IFERROR((W5/U5)/(V5/T5),""))
A6: ENG-05 | B6: Landscape & Civil Design | C6: Engineering | D6: Engineering & Design Fees | E6: P1 | F6: 45334 | G6: 45350 | H6: 45334 | I6: 45350 | J6: 45334 | K6: 45350 | L6: 1 | M6: =IF(L6=1,IF(K6>G6,"Delayed","Completed"),IF(L6=0,"Not Started",IF(I6>G6,"Delayed","In Progress"))) -> Completed | N6: =I6-G6 -> 0 | O6: - | P6: None | Q6: 15000 | R6: 15000 | S6: 15000 | Y6: =IF(OR(T6="",U6=""),"",IFERROR((W6/U6)/(V6/T6),""))
A7: ENG-06 | B7: Fire & Life Safety Design | C7: Engineering | D7: Engineering & Design Fees | E7: P2 | F7: 45352 | G7: 45369 | H7: 45352 | I7: 45373 | J7: 45352 | K7: 45373 | L7: 1 | M7: =IF(L7=1,IF(K7>G7,"Delayed","Completed"),IF(L7=0,"Not Started",IF(I7>G7,"Delayed","In Progress"))) -> Delayed | N7: =I7-G7 -> 4 | O7: Code compliance revisions | P7: Low | Q7: 25000 | R7: 26500 | S7: 26500 | Y7: =IF(OR(T7="",U7=""),"",IFERROR((W7/U7)/(V7/T7),""))
A8: ENG-07 | B8: Geotechnical Peer Review | C8: Engineering | D8: Engineering & Design Fees | E8: P1 | F8: 45330 | G8: 45342 | H8: 45330 | I8: 45342 | J8: 45330 | K8: 45342 | L8: 1 | M8: =IF(L8=1,IF(K8>G8,"Delayed","Completed"),IF(L8=0,"Not Started",IF(I8>G8,"Delayed","In Progress"))) -> Completed | N8: =I8-G8 -> 0 | O8: - | P8: None | Q8: 12000 | R8: 12000 | S8: 12000 | Y8: =IF(OR(T8="",U8=""),"",IFERROR((W8/U8)/(V8/T8),""))
A9: ENG-08 | B9: BIM Coordination Model - Final | C9: Engineering | D9: Engineering & Design Fees | E9: P2 | F9: 45356 | G9: 45376 | H9: 45356 | I9: 45381 | J9: 45356 | K9: 45381 | L9: 1 | M9: =IF(L9=1,IF(K9>G9,"Delayed","Completed"),IF(L9=0,"Not Started",IF(I9>G9,"Delayed","In Progress"))) -> Delayed | N9: =I9-G9 -> 5 | O9: Additional clash detection rounds | P9: Low | Q9: 28000 | R9: 29500 | S9: 29500 | Y9: =IF(OR(T9="",U9=""),"",IFERROR((W9/U9)/(V9/T9),""))

Sheet Activities - Procurement
A1: Activity ID | B1: Activity Name | C1: Phase | D1: Cost Category | E1: Period | F1: Baseline Start | G1: Baseline Finish | H1: Forecast Start | I1: Forecast Finish | J1: Actual Start | K1: Actual Finish | L1: % Complete | M1: Status | N1: Variance (Days) | O1: Root Cause | P1: Impact | Q1: Budget Cost (AED) | R1: Actual Cost (AED) | S1: Forecast Cost (AED) | T1: Planned Hours | U1: Actual Hours | V1: Planned Output | W1: Actual Output | X1: Output Unit | Y1: Productivity Index
A2: PRC-01 | B2: Rebar Procurement | C2: Procurement | D2: Material Procurement | E2: P2 | F2: 45342 | G2: 45356 | H2: 45342 | I2: 45356 | J2: 45342 | K2: 45356 | L2: 1 | M2: =IF(L2=1,IF(K2>G2,"Delayed","Completed"),IF(L2=0,"Not Started",IF(I2>G2,"Delayed","In Progress"))) -> Completed | N2: =I2-G2 -> 0 | O2: - | P2: None | Q2: 60000 | R2: 60000 | S2: 60000 | Y2: =IF(OR(T2="",U2=""),"",IFERROR((W2/U2)/(V2/T2),""))
A3: PRC-02 | B3: Ready-Mix Concrete Supplier Contract | C3: Procurement | D3: Material Procurement | E3: P2 | F3: 45347 | G3: 45359 | H3: 45350 | I3: 45365 | J3: 45350 | K3: 45365 | L3: 1 | M3: =IF(L3=1,IF(K3>G3,"Delayed","Completed"),IF(L3=0,"Not Started",IF(I3>G3,"Delayed","In Progress"))) -> Delayed | N3: =I3-G3 -> 6 | O3: Supplier price renegotiation | P3: Medium | Q3: 70000 | R3: 68000 | S3: 70000 | Y3: =IF(OR(T3="",U3=""),"",IFERROR((W3/U3)/(V3/T3),""))
A4: PRC-03 | B4: Structural Steel Procurement | C4: Procurement | D4: Material Procurement | E4: P2 | F4: 45352 | G4: 45371 | H4: 45356 | I4: 45381 | J4: 45356 | K4: 45381 | L4: 1 | M4: =IF(L4=1,IF(K4>G4,"Delayed","Completed"),IF(L4=0,"Not Started",IF(I4>G4,"Delayed","In Progress"))) -> Delayed | N4: =I4-G4 -> 10 | O4: Mill lead-time longer than quoted | P4: High | Q4: 100000 | R4: 95000 | S4: 98000 | Y4: =IF(OR(T4="",U4=""),"",IFERROR((W4/U4)/(V4/T4),""))
A5: PRC-04 | B5: MEP Equipment Long-Lead Items | C5: Procurement | D5: Material Procurement | E5: P3 | F5: 45356 | G5: 45383 | H5: 45361 | I5: 45415 | J5: 45361 | L5: 0.7 | M5: =IF(L5=1,IF(K5>G5,"Delayed","Completed"),IF(L5=0,"Not Started",IF(I5>G5,"Delayed","In Progress"))) -> Delayed | N5: =I5-G5 -> 32 | O5: Chiller delivery delayed by manufacturer | P5: High | Q5: 80000 | R5: 75000 | S5: 77000 | Y5: =IF(OR(T5="",U5=""),"",IFERROR((W5/U5)/(V5/T5),""))
A6: PRC-05 | B6: Elevator & Lift Package | C6: Procurement | D6: Vertical Transportation | E6: P2 | F6: 45361 | G6: 45392 | H6: 45363 | I6: 45402 | J6: 45363 | L6: 0.8 | M6: =IF(L6=1,IF(K6>G6,"Delayed","Completed"),IF(L6=0,"Not Started",IF(I6>G6,"Delayed","In Progress"))) -> Delayed | N6: =I6-G6 -> 10 | O6: OEM factory backlog | P6: Medium | Q6: 220000 | R6: 180000 | S6: 225000 | Y6: =IF(OR(T6="",U6=""),"",IFERROR((W6/U6)/(V6/T6),""))
A7: PRC-06 | B7: Facade & Glazing Package | C7: Procurement | D7: Facade & Glazing | E7: P3 | F7: 45371 | G7: 45397 | H7: 45376 | I7: 45412 | J7: 45376 | L7: 0.5 | M7: =IF(L7=1,IF(K7>G7,"Delayed","Completed"),IF(L7=0,"Not Started",IF(I7>G7,"Delayed","In Progress"))) -> Delayed | N7: =I7-G7 -> 15 | O7: Custom glass unit lead time | P7: High | Q7: 260000 | R7: 140000 | S7: 270000 | Y7: =IF(OR(T7="",U7=""),"",IFERROR((W7/U7)/(V7/T7),""))
A8: PRC-07 | B8: Interior Finishes Materials Package | C8: Procurement | D8: Fit-Out & Finishes | E8: P3 | F8: 45387 | G8: 45407 | H8: 45390 | I8: 45414 | J8: 45390 | L8: 0.6 | M8: =IF(L8=1,IF(K8>G8,"Delayed","Completed"),IF(L8=0,"Not Started",IF(I8>G8,"Delayed","In Progress"))) -> Delayed | N8: =I8-G8 -> 7 | O8: Tile supplier backorder | P8: Medium | Q8: 95000 | R8: 58000 | S8: 98000 | Y8: =IF(OR(T8="",U8=""),"",IFERROR((W8/U8)/(V8/T8),""))
A9: PRC-08 | B9: Landscaping Materials & Plants | C9: Procurement | D9: Landscaping & External Works | E9: P4 | F9: 45427 | G9: 45442 | H9: 45427 | I9: 45442 | L9: 0 | M9: =IF(L9=1,IF(K9>G9,"Delayed","Completed"),IF(L9=0,"Not Started",IF(I9>G9,"Delayed","In Progress"))) -> Not Started | N9: =I9-G9 -> 0 | O9: - | P9: None | Q9: 40000 | R9: 0 | S9: 40000 | Y9: =IF(OR(T9="",U9=""),"",IFERROR((W9/U9)/(V9/T9),""))

Sheet Activities - Construction
A1: Activity ID | B1: Activity Name | C1: Phase | D1: Cost Category | E1: Period | F1: Baseline Start | G1: Baseline Finish | H1: Forecast Start | I1: Forecast Finish | J1: Actual Start | K1: Actual Finish | L1: % Complete | M1: Status | N1: Variance (Days) | O1: Root Cause | P1: Impact | Q1: Budget Cost (AED) | R1: Actual Cost (AED) | S1: Forecast Cost (AED) | T1: Planned Hours | U1: Actual Hours | V1: Planned Output | W1: Actual Output | X1: Output Unit | Y1: Productivity Index
A2: CON-01 | B2: Excavation & Shoring | C2: Construction | D2: Civil Works | E2: P2 | F2: 45352 | G2: 45366 | H2: 45354 | I2: 45371 | J2: 45354 | K2: 45371 | L2: 1 | M2: =IF(L2=1,IF(K2>G2,"Delayed","Completed"),IF(L2=0,"Not Started",IF(I2>G2,"Delayed","In Progress"))) -> Delayed | N2: =I2-G2 -> 5 | O2: Groundwater management | P2: Medium | Q2: 80000 | R2: 85000 | S2: 88000 | T2: 4200 | U2: 4850 | V2: 620 | W2: 540 | X2: m3 poured | Y2: =IF(OR(T2="",U2=""),"",IFERROR((W2/U2)/(V2/T2),"")) -> 0.75424011
A3: CON-02 | B3: Foundation & Raft Slab Pour | C3: Construction | D3: Civil Works | E3: P2 | F3: 45361 | G3: 45379 | H3: 45366 | I3: 45387 | J3: 45366 | K3: 45387 | L3: 1 | M3: =IF(L3=1,IF(K3>G3,"Delayed","Completed"),IF(L3=0,"Not Started",IF(I3>G3,"Delayed","In Progress"))) -> Delayed | N3: =I3-G3 -> 8 | O3: Rebar procurement delay upstream | P3: High | Q3: 120000 | R3: 128000 | S3: 132000 | T3: 3100 | U3: 3400 | V3: 85 | W3: 76 | X3: tons fixed | Y3: =IF(OR(T3="",U3=""),"",IFERROR((W3/U3)/(V3/T3),"")) -> 0.81522491
A4: CON-03 | B4: Substructure Waterproofing | C4: Construction | D4: Civil Works | E4: P3 | F4: 45376 | G4: 45387 | H4: 45383 | I4: 45410 | J4: 45383 | L4: 0.6 | M4: =IF(L4=1,IF(K4>G4,"Delayed","Completed"),IF(L4=0,"Not Started",IF(I4>G4,"Delayed","In Progress"))) -> Delayed | N4: =I4-G4 -> 23 | O4: Follows foundation pour completion | P4: Medium | Q4: 60000 | R4: 62000 | S4: 64000 | T4: 1800 | U4: 1650 | V4: 40 | W4: 34 | X4: tons erected | Y4: =IF(OR(T4="",U4=""),"",IFERROR((W4/U4)/(V4/T4),"")) -> 0.92727273
A5: CON-04 | B5: Superstructure - Ground to L3 Columns | C5: Construction | D5: Civil Works | E5: P3 | F5: 45383 | G5: 45407 | H5: 45385 | I5: 45414 | J5: 45385 | L5: 0.45 | M5: =IF(L5=1,IF(K5>G5,"Delayed","Completed"),IF(L5=0,"Not Started",IF(I5>G5,"Delayed","In Progress"))) -> Delayed | N5: =I5-G5 -> 7 | O5: Concrete supplier renegotiation impact | P5: High | Q5: 90000 | R5: 95000 | S5: 98000 | T5: 2600 | U5: 2900 | V5: 310 | W5: 275 | X5: linear meters | Y5: =IF(OR(T5="",U5=""),"",IFERROR((W5/U5)/(V5/T5),"")) -> 0.79532814
A6: CON-05 | B6: Superstructure - Slab L1 | C6: Construction | D6: Civil Works | E6: P3 | F6: 45392 | G6: 45412 | H6: 45392 | I6: 45417 | L6: 0.15 | M6: =IF(L6=1,IF(K6>G6,"Delayed","Completed"),IF(L6=0,"Not Started",IF(I6>G6,"Delayed","In Progress"))) -> Delayed | N6: =I6-G6 -> 5 | O6: Sequenced after column pours | P6: Medium | Q6: 30000 | R6: 32500 | S6: 33000 | T6: 1500 | U6: 1400 | V6: 210 | W6: 205 | X6: m2 completed | Y6: =IF(OR(T6="",U6=""),"",IFERROR((W6/U6)/(V6/T6),"")) -> 1.0459184
A7: CON-06 | B7: Site Mobilization & Hoarding | C7: Construction | D7: Equipment Idle Time | E7: P1 | F7: 45323 | G7: 45329 | H7: 45323 | I7: 45329 | J7: 45323 | K7: 45329 | L7: 1 | M7: =IF(L7=1,IF(K7>G7,"Delayed","Completed"),IF(L7=0,"Not Started",IF(I7>G7,"Delayed","In Progress"))) -> Completed | N7: =I7-G7 -> 0 | O7: - | P7: None | Q7: 25000 | R7: 41200 | S7: 46000 | T7: 900 | U7: 1150 | V7: 1 | W7: 1 | X7: lump sum | Y7: =IF(OR(T7="",U7=""),"",IFERROR((W7/U7)/(V7/T7),"")) -> 0.7826087
A8: CON-07 | B8: MEP First Fix - L1-L3 | C8: Construction | D8: MEP Works | E8: P3 | F8: 45397 | G8: 45422 | H8: 45400 | I8: 45427 | J8: 45400 | L8: 0.3 | M8: =IF(L8=1,IF(K8>G8,"Delayed","Completed"),IF(L8=0,"Not Started",IF(I8>G8,"Delayed","In Progress"))) -> Delayed | N8: =I8-G8 -> 5 | O8: Sequenced after superstructure | P8: Medium | Q8: 140000 | R8: 45000 | S8: 145000 | T8: 2000 | U8: 650 | V8: 100 | W8: 28 | X8: risers installed | Y8: =IF(OR(T8="",U8=""),"",IFERROR((W8/U8)/(V8/T8),"")) -> 0.86153846
A9: CON-08 | B9: External Facade Installation - Phase 1 | C9: Construction | D9: Facade & Glazing | E9: P3 | F9: 45402 | G9: 45432 | H9: 45407 | I9: 45440 | L9: 0.1 | M9: =IF(L9=1,IF(K9>G9,"Delayed","Completed"),IF(L9=0,"Not Started",IF(I9>G9,"Delayed","In Progress"))) -> Delayed | N9: =I9-G9 -> 8 | O9: Awaiting glazing package delivery | P9: High | Q9: 180000 | R9: 15000 | S9: 190000 | T9: 1600 | U9: 120 | V9: 60 | W9: 5 | X9: panels installed | Y9: =IF(OR(T9="",U9=""),"",IFERROR((W9/U9)/(V9/T9),"")) -> 1.1111111
A10: CON-09 | B10: Internal Partitions - L1 | C10: Construction | D10: Fit-Out & Finishes | E10: P3 | F10: 45404 | G10: 45427 | H10: 45404 | I10: 45427 | L10: 0 | M10: =IF(L10=1,IF(K10>G10,"Delayed","Completed"),IF(L10=0,"Not Started",IF(I10>G10,"Delayed","In Progress"))) -> Not Started | N10: =I10-G10 -> 0 | O10: - | P10: None | Q10: 70000 | R10: 0 | S10: 70000 | T10: 800 | U10: 0 | V10: 900 | W10: 0 | X10: m2 partitions | Y10: =IF(OR(T10="",U10=""),"",IFERROR((W10/U10)/(V10/T10),""))
A11: OVH-01 | B11: Site Overheads & Indirect Labor | C11: Construction | D11: Labor & Site Overheads | E11: P3 | F11: 45323 | G11: 45412 | H11: 45323 | I11: 45412 | J11: 45323 | K11: 45412 | L11: 1 | M11: =IF(L11=1,IF(K11>G11,"Delayed","Completed"),IF(L11=0,"Not Started",IF(I11>G11,"Delayed","In Progress"))) -> Completed | N11: =I11-G11 -> 0 | O11: - | P11: None | Q11: 150000 | R11: 156800 | S11: 162000 | Y11: =IF(OR(T11="",U11=""),"",IFERROR((W11/U11)/(V11/T11),""))
A12: CNT-01 | B12: Contingency Reserve | C12: Construction | D12: Contingency Reserve | E12: P3 | F12: 45323 | G12: 45412 | H12: 45323 | I12: 45412 | J12: 45323 | K12: 45412 | L12: 1 | M12: =IF(L12=1,IF(K12>G12,"Delayed","Completed"),IF(L12=0,"Not Started",IF(I12>G12,"Delayed","In Progress"))) -> Completed | N12: =I12-G12 -> 0 | O12: - | P12: None | Q12: 50000 | R12: 6300 | S12: 12000 | Y12: =IF(OR(T12="",U12=""),"",IFERROR((W12/U12)/(V12/T12),""))
A13: CON-10 | B13: Roofing & Waterproofing - Roof Level | C13: Construction | D13: Civil Works | E13: P4 | F13: 45417 | G13: 45437 | H13: 45420 | I13: 45446 | J13: 45420 | L13: 0.4 | M13: =IF(L13=1,IF(K13>G13,"Delayed","Completed"),IF(L13=0,"Not Started",IF(I13>G13,"Delayed","In Progress"))) -> Delayed | N13: =I13-G13 -> 9 | O13: Sequenced after superstructure topping out | P13: Medium | Q13: 85000 | R13: 30000 | S13: 90000 | Y13: =IF(OR(T13="",U13=""),"",IFERROR((W13/U13)/(V13/T13),""))
A14: CON-11 | B14: External Hardscape & Paving | C14: Construction | D14: Landscaping & External Works | E14: P4 | F14: 45432 | G14: 45453 | H14: 45432 | I14: 45453 | L14: 0 | M14: =IF(L14=1,IF(K14>G14,"Delayed","Completed"),IF(L14=0,"Not Started",IF(I14>G14,"Delayed","In Progress"))) -> Not Started | N14: =I14-G14 -> 0 | O14: - | P14: None | Q14: 55000 | R14: 0 | S14: 55000 | Y14: =IF(OR(T14="",U14=""),"",IFERROR((W14/U14)/(V14/T14),""))

Sheet Activities - Commissioning
A1: Activity ID | B1: Activity Name | C1: Phase | D1: Cost Category | E1: Period | F1: Baseline Start | G1: Baseline Finish | H1: Forecast Start | I1: Forecast Finish | J1: Actual Start | K1: Actual Finish | L1: % Complete | M1: Status | N1: Variance (Days) | O1: Root Cause | P1: Impact | Q1: Budget Cost (AED) | R1: Actual Cost (AED) | S1: Forecast Cost (AED) | T1: Planned Hours | U1: Actual Hours | V1: Planned Output | W1: Actual Output | X1: Output Unit | Y1: Productivity Index
A2: COM-01 | B2: MEP Systems Testing & Balancing | C2: Commissioning | D2: Testing & Commissioning | E2: P4 | F2: 45422 | G2: 45437 | H2: 45424 | I2: 45445 | J2: 45424 | L2: 0.2 | M2: =IF(L2=1,IF(K2>G2,"Delayed","Completed"),IF(L2=0,"Not Started",IF(I2>G2,"Delayed","In Progress"))) -> Delayed | N2: =I2-G2 -> 8 | O2: Sequenced after MEP first fix completion | P2: Medium | Q2: 60000 | R2: 12000 | S2: 62000 | T2: 500 | U2: 100 | V2: 20 | W2: 4 | X2: systems tested | Y2: =IF(OR(T2="",U2=""),"",IFERROR((W2/U2)/(V2/T2),"")) -> 1
A3: COM-02 | B3: Fire Alarm & Life Safety Commissioning | C3: Commissioning | D3: Testing & Commissioning | E3: P4 | F3: 45432 | G3: 45448 | H3: 45432 | I3: 45448 | L3: 0 | M3: =IF(L3=1,IF(K3>G3,"Delayed","Completed"),IF(L3=0,"Not Started",IF(I3>G3,"Delayed","In Progress"))) -> Not Started | N3: =I3-G3 -> 0 | O3: - | P3: None | Q3: 35000 | R3: 0 | S3: 35000 | Y3: =IF(OR(T3="",U3=""),"",IFERROR((W3/U3)/(V3/T3),""))
A4: COM-03 | B4: Snagging & Defects Rectification | C4: Commissioning | D4: Snagging & Handover | E4: P4 | F4: 45437 | G4: 45458 | H4: 45440 | I4: 45463 | L4: 0 | M4: =IF(L4=1,IF(K4>G4,"Delayed","Completed"),IF(L4=0,"Not Started",IF(I4>G4,"Delayed","In Progress"))) -> Not Started | N4: =I4-G4 -> 5 | O4: Follows facade and fit-out completion | P4: Medium | Q4: 45000 | R4: 0 | S4: 48000 | Y4: =IF(OR(T4="",U4=""),"",IFERROR((W4/U4)/(V4/T4),""))
A5: COM-04 | B5: As-Built Documentation & O&M Manuals | C5: Commissioning | D5: Snagging & Handover | E5: P4 | F5: 45444 | G5: 45458 | H5: 45444 | I5: 45458 | L5: 0 | M5: =IF(L5=1,IF(K5>G5,"Delayed","Completed"),IF(L5=0,"Not Started",IF(I5>G5,"Delayed","In Progress"))) -> Not Started | N5: =I5-G5 -> 0 | O5: - | P5: None | Q5: 20000 | R5: 0 | S5: 20000 | Y5: =IF(OR(T5="",U5=""),"",IFERROR((W5/U5)/(V5/T5),""))
A6: COM-05 | B6: Client Handover & Training | C6: Commissioning | D6: Snagging & Handover | E6: P4 | F6: 45459 | G6: 45463 | H6: 45459 | I6: 45463 | L6: 0 | M6: =IF(L6=1,IF(K6>G6,"Delayed","Completed"),IF(L6=0,"Not Started",IF(I6>G6,"Delayed","In Progress"))) -> Not Started | N6: =I6-G6 -> 0 | O6: - | P6: None | Q6: 15000 | R6: 0 | S6: 15000 | Y6: =IF(OR(T6="",U6=""),"",IFERROR((W6/U6)/(V6/T6),""))

Sheet Schedule Intelligence
A1: Activity ID | B1: Activity Name | C1: Phase | D1: Status | E1: Variance (Days) | F1: Root Cause | G1: Impact
A2: ='Activities - Engineering'!A3 -> ENG-02 | B2: ='Activities - Engineering'!B3 -> Architectural Drawings - IFC | C2: ='Activities - Engineering'!C3 -> Engineering | D2: ='Activities - Engineering'!M3 -> Delayed | E2: ='Activities - Engineering'!N3 -> 6 | F2: ='Activities - Engineering'!O3 -> Client review delays | G2: ='Activities - Engineering'!P3 -> Low
A3: ='Activities - Engineering'!A4 -> ENG-03 | B3: ='Activities - Engineering'!B4 -> Structural Design & Calculations | C3: ='Activities - Engineering'!C4 -> Engineering | D3: ='Activities - Engineering'!M4 -> Delayed | E3: ='Activities - Engineering'!N4 -> 3 | F3: ='Activities - Engineering'!O4 -> Late input from geotech report | G3: ='Activities - Engineering'!P4 -> Medium
A4: ='Activities - Engineering'!A5 -> ENG-04 | B4: ='Activities - Engineering'!B5 -> MEP Coordination Drawings | C4: ='Activities - Engineering'!C5 -> Engineering | D4: ='Activities - Engineering'!M5 -> Delayed | E4: ='Activities - Engineering'!N5 -> 5 | F4: ='Activities - Engineering'!O5 -> Design clashes requiring rework | G4: ='Activities - Engineering'!P5 -> Medium
A5: ='Activities - Engineering'!A7 -> ENG-06 | B5: ='Activities - Engineering'!B7 -> Fire & Life Safety Design | C5: ='Activities - Engineering'!C7 -> Engineering | D5: ='Activities - Engineering'!M7 -> Delayed | E5: ='Activities - Engineering'!N7 -> 4 | F5: ='Activities - Engineering'!O7 -> Code compliance revisions | G5: ='Activities - Engineering'!P7 -> Low
A6: ='Activities - Engineering'!A9 -> ENG-08 | B6: ='Activities - Engineering'!B9 -> BIM Coordination Model - Final | C6: ='Activities - Engineering'!C9 -> Engineering | D6: ='Activities - Engineering'!M9 -> Delayed | E6: ='Activities - Engineering'!N9 -> 5 | F6: ='Activities - Engineering'!O9 -> Additional clash detection rounds | G6: ='Activities - Engineering'!P9 -> Low
A7: ='Activities - Procurement'!A3 -> PRC-02 | B7: ='Activities - Procurement'!B3 -> Ready-Mix Concrete Supplier Contract | C7: ='Activities - Procurement'!C3 -> Procurement | D7: ='Activities - Procurement'!M3 -> Delayed | E7: ='Activities - Procurement'!N3 -> 6 | F7: ='Activities - Procurement'!O3 -> Supplier price renegotiation | G7: ='Activities - Procurement'!P3 -> Medium
A8: ='Activities - Procurement'!A4 -> PRC-03 | B8: ='Activities - Procurement'!B4 -> Structural Steel Procurement | C8: ='Activities - Procurement'!C4 -> Procurement | D8: ='Activities - Procurement'!M4 -> Delayed | E8: ='Activities - Procurement'!N4 -> 10 | F8: ='Activities - Procurement'!O4 -> Mill lead-time longer than quoted | G8: ='Activities - Procurement'!P4 -> High
A9: ='Activities - Procurement'!A5 -> PRC-04 | B9: ='Activities - Procurement'!B5 -> MEP Equipment Long-Lead Items | C9: ='Activities - Procurement'!C5 -> Procurement | D9: ='Activities - Procurement'!M5 -> Delayed | E9: ='Activities - Procurement'!N5 -> 32 | F9: ='Activities - Procurement'!O5 -> Chiller delivery delayed by manufacturer | G9: ='Activities - Procurement'!P5 -> High
A10: ='Activities - Procurement'!A6 -> PRC-05 | B10: ='Activities - Procurement'!B6 -> Elevator & Lift Package | C10: ='Activities - Procurement'!C6 -> Procurement | D10: ='Activities - Procurement'!M6 -> Delayed | E10: ='Activities - Procurement'!N6 -> 10 | F10: ='Activities - Procurement'!O6 -> OEM factory backlog | G10: ='Activities - Procurement'!P6 -> Medium
A11: ='Activities - Procurement'!A7 -> PRC-06 | B11: ='Activities - Procurement'!B7 -> Facade & Glazing Package | C11: ='Activities - Procurement'!C7 -> Procurement | D11: ='Activities - Procurement'!M7 -> Delayed | E11: ='Activities - Procurement'!N7 -> 15 | F11: ='Activities - Procurement'!O7 -> Custom glass unit lead time | G11: ='Activities - Procurement'!P7 -> High
A12: ='Activities - Procurement'!A8 -> PRC-07 | B12: ='Activities - Procurement'!B8 -> Interior Finishes Materials Package | C12: ='Activities - Procurement'!C8 -> Procurement | D12: ='Activities - Procurement'!M8 -> Delayed | E12: ='Activities - Procurement'!N8 -> 7 | F12: ='Activities - Procurement'!O8 -> Tile supplier backorder | G12: ='Activities - Procurement'!P8 -> Medium
A13: ='Activities - Procurement'!A9 -> PRC-08 | B13: ='Activities - Procurement'!B9 -> Landscaping Materials & Plants | C13: ='Activities - Procurement'!C9 -> Procurement | D13: ='Activities - Procurement'!M9 -> Not Started | E13: ='Activities - Procurement'!N9 -> 0 | F13: ='Activities - Procurement'!O9 -> - | G13: ='Activities - Procurement'!P9 -> None
A14: ='Activities - Construction'!A2 -> CON-01 | B14: ='Activities - Construction'!B2 -> Excavation & Shoring | C14: ='Activities - Construction'!C2 -> Construction | D14: ='Activities - Construction'!M2 -> Delayed | E14: ='Activities - Construction'!N2 -> 5 | F14: ='Activities - Construction'!O2 -> Groundwater management | G14: ='Activities - Construction'!P2 -> Medium
A15: ='Activities - Construction'!A3 -> CON-02 | B15: ='Activities - Construction'!B3 -> Foundation & Raft Slab Pour | C15: ='Activities - Construction'!C3 -> Construction | D15: ='Activities - Construction'!M3 -> Delayed | E15: ='Activities - Construction'!N3 -> 8 | F15: ='Activities - Construction'!O3 -> Rebar procurement delay upstream | G15: ='Activities - Construction'!P3 -> High
A16: ='Activities - Construction'!A4 -> CON-03 | B16: ='Activities - Construction'!B4 -> Substructure Waterproofing | C16: ='Activities - Construction'!C4 -> Construction | D16: ='Activities - Construction'!M4 -> Delayed | E16: ='Activities - Construction'!N4 -> 23 | F16: ='Activities - Construction'!O4 -> Follows foundation pour completion | G16: ='Activities - Construction'!P4 -> Medium
A17: ='Activities - Construction'!A5 -> CON-04 | B17: ='Activities - Construction'!B5 -> Superstructure - Ground to L3 Columns | C17: ='Activities - Construction'!C5 -> Construction | D17: ='Activities - Construction'!M5 -> Delayed | E17: ='Activities - Construction'!N5 -> 7 | F17: ='Activities - Construction'!O5 -> Concrete supplier renegotiation impact | G17: ='Activities - Construction'!P5 -> High
A18: ='Activities - Construction'!A6 -> CON-05 | B18: ='Activities - Construction'!B6 -> Superstructure - Slab L1 | C18: ='Activities - Construction'!C6 -> Construction | D18: ='Activities - Construction'!M6 -> Delayed | E18: ='Activities - Construction'!N6 -> 5 | F18: ='Activities - Construction'!O6 -> Sequenced after column pours | G18: ='Activities - Construction'!P6 -> Medium
A19: ='Activities - Construction'!A8 -> CON-07 | B19: ='Activities - Construction'!B8 -> MEP First Fix - L1-L3 | C19: ='Activities - Construction'!C8 -> Construction | D19: ='Activities - Construction'!M8 -> Delayed | E19: ='Activities - Construction'!N8 -> 5 | F19: ='Activities - Construction'!O8 -> Sequenced after superstructure | G19: ='Activities - Construction'!P8 -> Medium
A20: ='Activities - Construction'!A9 -> CON-08 | B20: ='Activities - Construction'!B9 -> External Facade Installation - Phase 1 | C20: ='Activities - Construction'!C9 -> Construction | D20: ='Activities - Construction'!M9 -> Delayed | E20: ='Activities - Construction'!N9 -> 8 | F20: ='Activities - Construction'!O9 -> Awaiting glazing package delivery | G20: ='Activities - Construction'!P9 -> High
A21: ='Activities - Construction'!A10 -> CON-09 | B21: ='Activities - Construction'!B10 -> Internal Partitions - L1 | C21: ='Activities - Construction'!C10 -> Construction | D21: ='Activities - Construction'!M10 -> Not Started | E21: ='Activities - Construction'!N10 -> 0 | F21: ='Activities - Construction'!O10 -> - | G21: ='Activities - Construction'!P10 -> None
A22: ='Activities - Construction'!A13 -> CON-10 | B22: ='Activities - Construction'!B13 -> Roofing & Waterproofing - Roof Level | C22: ='Activities - Construction'!C13 -> Construction | D22: ='Activities - Construction'!M13 -> Delayed | E22: ='Activities - Construction'!N13 -> 9 | F22: ='Activities - Construction'!O13 -> Sequenced after superstructure topping out | G22: ='Activities - Construction'!P13 -> Medium
A23: ='Activities - Construction'!A14 -> CON-11 | B23: ='Activities - Construction'!B14 -> External Hardscape & Paving | C23: ='Activities - Construction'!C14 -> Construction | D23: ='Activities - Construction'!M14 -> Not Started | E23: ='Activities - Construction'!N14 -> 0 | F23: ='Activities - Construction'!O14 -> - | G23: ='Activities - Construction'!P14 -> None
A24: ='Activities - Commissioning'!A2 -> COM-01 | B24: ='Activities - Commissioning'!B2 -> MEP Systems Testing & Balancing | C24: ='Activities - Commissioning'!C2 -> Commissioning | D24: ='Activities - Commissioning'!M2 -> Delayed | E24: ='Activities - Commissioning'!N2 -> 8 | F24: ='Activities - Commissioning'!O2 -> Sequenced after MEP first fix completion | G24: ='Activities - Commissioning'!P2 -> Medium
A25: ='Activities - Commissioning'!A3 -> COM-02 | B25: ='Activities - Commissioning'!B3 -> Fire Alarm & Life Safety Commissioning | C25: ='Activities - Commissioning'!C3 -> Commissioning | D25: ='Activities - Commissioning'!M3 -> Not Started | E25: ='Activities - Commissioning'!N3 -> 0 | F25: ='Activities - Commissioning'!O3 -> - | G25: ='Activities - Commissioning'!P3 -> None
A26: ='Activities - Commissioning'!A4 -> COM-03 | B26: ='Activities - Commissioning'!B4 -> Snagging & Defects Rectification | C26: ='Activities - Commissioning'!C4 -> Commissioning | D26: ='Activities - Commissioning'!M4 -> Not Started | E26: ='Activities - Commissioning'!N4 -> 5 | F26: ='Activities - Commissioning'!O4 -> Follows facade and fit-out completion | G26: ='Activities - Commissioning'!P4 -> Medium
A27: ='Activities - Commissioning'!A5 -> COM-04 | B27: ='Activities - Commissioning'!B5 -> As-Built Documentation & O&M Manuals | C27: ='Activities - Commissioning'!C5 -> Commissioning | D27: ='Activities - Commissioning'!M5 -> Not Started | E27: ='Activities - Commissioning'!N5 -> 0 | F27: ='Activities - Commissioning'!O5 -> - | G27: ='Activities - Commissioning'!P5 -> None
A28: ='Activities - Commissioning'!A6 -> COM-05 | B28: ='Activities - Commissioning'!B6 -> Client Handover & Training | C28: ='Activities - Commissioning'!C6 -> Commissioning | D28: ='Activities - Commissioning'!M6 -> Not Started | E28: ='Activities - Commissioning'!N6 -> 0 | F28: ='Activities - Commissioning'!O6 -> - | G28: ='Activities - Commissioning'!P6 -> None

Sheet Cost Intelligence
A1: Cost Category | B1: P1 (AED) | C1: P2 (AED) | D1: P3 (AED) | E1: P4 (AED) | F1: Fcst (AED) | G1: Variance vs Budget | H1: % of Budget
A2: Civil Works | B2: =SUMIFS('Activities - Engineering'!R2:R9,'Activities - Engineering'!D2:D9,A2,'Activities - Engineering'!E2:E9,"P1")+SUMIFS('Activities - Procurement'!R2:R9,'Activities - Procurement'!D2:D9,A2,'Activities - Procurement'!E2:E9,"P1")+SUMIFS('Activities - Construction'!R2:R14,'Activities - Construction'!D2:D14,A2,'Activities - Construction'!E2:E14,"P1")+SUMIFS('Activities - Commissioning'!R2:R6,'Activities - Commissioning'!D2:D6,A2,'Activities - Commissioning'!E2:E6,"P1") -> 0 | C2: =SUMIFS('Activities - Engineering'!R2:R9,'Activities - Engineering'!D2:D9,A2,'Activities - Engineering'!E2:E9,"P2")+SUMIFS('Activities - Procurement'!R2:R9,'Activities - Procurement'!D2:D9,A2,'Activities - Procurement'!E2:E9,"P2")+SUMIFS('Activities - Construction'!R2:R14,'Activities - Construction'!D2:D14,A2,'Activities - Construction'!E2:E14,"P2")+SUMIFS('Activities - Commissioning'!R2:R6,'Activities - Commissioning'!D2:D6,A2,'Activities - Commissioning'!E2:E6,"P2") -> 213000 | D2: =SUMIFS('Activities - Engineering'!R2:R9,'Activities - Engineering'!D2:D9,A2,'Activities - Engineering'!E2:E9,"P3")+SUMIFS('Activities - Procurement'!R2:R9,'Activities - Procurement'!D2:D9,A2,'Activities - Procurement'!E2:E9,"P3")+SUMIFS('Activities - Construction'!R2:R14,'Activities - Construction'!D2:D14,A2,'Activities - Construction'!E2:E14,"P3")+SUMIFS('Activities - Commissioning'!R2:R6,'Activities - Commissioning'!D2:D6,A2,'Activities - Commissioning'!E2:E6,"P3") -> 189500 | E2: =SUMIFS('Activities - Engineering'!R2:R9,'Activities - Engineering'!D2:D9,A2,'Activities - Engineering'!E2:E9,"P4")+SUMIFS('Activities - Procurement'!R2:R9,'Activities - Procurement'!D2:D9,A2,'Activities - Procurement'!E2:E9,"P4")+SUMIFS('Activities - Construction'!R2:R14,'Activities - Construction'!D2:D14,A2,'Activities - Construction'!E2:E14,"P4")+SUMIFS('Activities - Commissioning'!R2:R6,'Activities - Commissioning'!D2:D6,A2,'Activities - Commissioning'!E2:E6,"P4") -> 30000 | F2: =SUMIF('Activities - Engineering'!D2:D9,A2,'Activities - Engineering'!S2:S9)+SUMIF('Activities - Procurement'!D2:D9,A2,'Activities - Procurement'!S2:S9)+SUMIF('Activities - Construction'!D2:D14,A2,'Activities - Construction'!S2:S14)+SUMIF('Activities - Commissioning'!D2:D6,A2,'Activities - Commissioning'!S2:S6) -> 505000 | G2: =F2-(SUMIF('Activities - Engineering'!D2:D9,A2,'Activities - Engineering'!Q2:Q9)+SUMIF('Activities - Procurement'!D2:D9,A2,'Activities - Procurement'!Q2:Q9)+SUMIF('Activities - Construction'!D2:D14,A2,'Activities - Construction'!Q2:Q14)+SUMIF('Activities - Commissioning'!D2:D6,A2,'Activities - Commissioning'!Q2:Q6)) -> 40000 | H2: =IFERROR(F2/(SUMIF('Activities - Engineering'!D2:D9,A2,'Activities - Engineering'!Q2:Q9)+SUMIF('Activities - Procurement'!D2:D9,A2,'Activities - Procurement'!Q2:Q9)+SUMIF('Activities - Construction'!D2:D14,A2,'Activities - Construction'!Q2:Q14)+SUMIF('Activities - Commissioning'!D2:D6,A2,'Activities - Commissioning'!Q2:Q6)),0) -> 1.0860215
A3: Material Procurement | B3: =SUMIFS('Activities - Engineering'!R2:R9,'Activities - Engineering'!D2:D9,A3,'Activities - Engineering'!E2:E9,"P1")+SUMIFS('Activities - Procurement'!R2:R9,'Activities - Procurement'!D2:D9,A3,'Activities - Procurement'!E2:E9,"P1")+SUMIFS('Activities - Construction'!R2:R14,'Activities - Construction'!D2:D14,A3,'Activities - Construction'!E2:E14,"P1")+SUMIFS('Activities - Commissioning'!R2:R6,'Activities - Commissioning'!D2:D6,A3,'Activities - Commissioning'!E2:E6,"P1") -> 0 | C3: =SUMIFS('Activities - Engineering'!R2:R9,'Activities - Engineering'!D2:D9,A3,'Activities - Engineering'!E2:E9,"P2")+SUMIFS('Activities - Procurement'!R2:R9,'Activities - Procurement'!D2:D9,A3,'Activities - Procurement'!E2:E9,"P2")+SUMIFS('Activities - Construction'!R2:R14,'Activities - Construction'!D2:D14,A3,'Activities - Construction'!E2:E14,"P2")+SUMIFS('Activities - Commissioning'!R2:R6,'Activities - Commissioning'!D2:D6,A3,'Activities - Commissioning'!E2:E6,"P2") -> 223000 | D3: =SUMIFS('Activities - Engineering'!R2:R9,'Activities - Engineering'!D2:D9,A3,'Activities - Engineering'!E2:E9,"P3")+SUMIFS('Activities - Procurement'!R2:R9,'Activities - Procurement'!D2:D9,A3,'Activities - Procurement'!E2:E9,"P3")+SUMIFS('Activities - Construction'!R2:R14,'Activities - Construction'!D2:D14,A3,'Activities - Construction'!E2:E14,"P3")+SUMIFS('Activities - Commissioning'!R2:R6,'Activities - Commissioning'!D2:D6,A3,'Activities - Commissioning'!E2:E6,"P3") -> 75000 | E3: =SUMIFS('Activities - Engineering'!R2:R9,'Activities - Engineering'!D2:D9,A3,'Activities - Engineering'!E2:E9,"P4")+SUMIFS('Activities - Procurement'!R2:R9,'Activities - Procurement'!D2:D9,A3,'Activities - Procurement'!E2:E9,"P4")+SUMIFS('Activities - Construction'!R2:R14,'Activities - Construction'!D2:D14,A3,'Activities - Construction'!E2:E14,"P4")+SUMIFS('Activities - Commissioning'!R2:R6,'Activities - Commissioning'!D2:D6,A3,'Activities - Commissioning'!E2:E6,"P4") -> 0 | F3: =SUMIF('Activities - Engineering'!D2:D9,A3,'Activities - Engineering'!S2:S9)+SUMIF('Activities - Procurement'!D2:D9,A3,'Activities - Procurement'!S2:S9)+SUMIF('Activities - Construction'!D2:D14,A3,'Activities - Construction'!S2:S14)+SUMIF('Activities - Commissioning'!D2:D6,A3,'Activities - Commissioning'!S2:S6) -> 305000 | G3: =F3-(SUMIF('Activities - Engineering'!D2:D9,A3,'Activities - Engineering'!Q2:Q9)+SUMIF('Activities - Procurement'!D2:D9,A3,'Activities - Procurement'!Q2:Q9)+SUMIF('Activities - Construction'!D2:D14,A3,'Activities - Construction'!Q2:Q14)+SUMIF('Activities - Commissioning'!D2:D6,A3,'Activities - Commissioning'!Q2:Q6)) -> -5000 | H3: =IFERROR(F3/(SUMIF('Activities - Engineering'!D2:D9,A3,'Activities - Engineering'!Q2:Q9)+SUMIF('Activities - Procurement'!D2:D9,A3,'Activities - Procurement'!Q2:Q9)+SUMIF('Activities - Construction'!D2:D14,A3,'Activities - Construction'!Q2:Q14)+SUMIF('Activities - Commissioning'!D2:D6,A3,'Activities - Commissioning'!Q2:Q6)),0) -> 0.98387097
A4: Equipment Idle Time | B4: =SUMIFS('Activities - Engineering'!R2:R9,'Activities - Engineering'!D2:D9,A4,'Activities - Engineering'!E2:E9,"P1")+SUMIFS('Activities - Procurement'!R2:R9,'Activities - Procurement'!D2:D9,A4,'Activities - Procurement'!E2:E9,"P1")+SUMIFS('Activities - Construction'!R2:R14,'Activities - Construction'!D2:D14,A4,'Activities - Construction'!E2:E14,"P1")+SUMIFS('Activities - Commissioning'!R2:R6,'Activities - Commissioning'!D2:D6,A4,'Activities - Commissioning'!E2:E6,"P1") -> 41200 | C4: =SUMIFS('Activities - Engineering'!R2:R9,'Activities - Engineering'!D2:D9,A4,'Activities - Engineering'!E2:E9,"P2")+SUMIFS('Activities - Procurement'!R2:R9,'Activities - Procurement'!D2:D9,A4,'Activities - Procurement'!E2:E9,"P2")+SUMIFS('Activities - Construction'!R2:R14,'Activities - Construction'!D2:D14,A4,'Activities - Construction'!E2:E14,"P2")+SUMIFS('Activities - Commissioning'!R2:R6,'Activities - Commissioning'!D2:D6,A4,'Activities - Commissioning'!E2:E6,"P2") -> 0 | D4: =SUMIFS('Activities - Engineering'!R2:R9,'Activities - Engineering'!D2:D9,A4,'Activities - Engineering'!E2:E9,"P3")+SUMIFS('Activities - Procurement'!R2:R9,'Activities - Procurement'!D2:D9,A4,'Activities - Procurement'!E2:E9,"P3")+SUMIFS('Activities - Construction'!R2:R14,'Activities - Construction'!D2:D14,A4,'Activities - Construction'!E2:E14,"P3")+SUMIFS('Activities - Commissioning'!R2:R6,'Activities - Commissioning'!D2:D6,A4,'Activities - Commissioning'!E2:E6,"P3") -> 0 | E4: =SUMIFS('Activities - Engineering'!R2:R9,'Activities - Engineering'!D2:D9,A4,'Activities - Engineering'!E2:E9,"P4")+SUMIFS('Activities - Procurement'!R2:R9,'Activities - Procurement'!D2:D9,A4,'Activities - Procurement'!E2:E9,"P4")+SUMIFS('Activities - Construction'!R2:R14,'Activities - Construction'!D2:D14,A4,'Activities - Construction'!E2:E14,"P4")+SUMIFS('Activities - Commissioning'!R2:R6,'Activities - Commissioning'!D2:D6,A4,'Activities - Commissioning'!E2:E6,"P4") -> 0 | F4: =SUMIF('Activities - Engineering'!D2:D9,A4,'Activities - Engineering'!S2:S9)+SUMIF('Activities - Procurement'!D2:D9,A4,'Activities - Procurement'!S2:S9)+SUMIF('Activities - Construction'!D2:D14,A4,'Activities - Construction'!S2:S14)+SUMIF('Activities - Commissioning'!D2:D6,A4,'Activities - Commissioning'!S2:S6) -> 46000 | G4: =F4-(SUMIF('Activities - Engineering'!D2:D9,A4,'Activities - Engineering'!Q2:Q9)+SUMIF('Activities - Procurement'!D2:D9,A4,'Activities - Procurement'!Q2:Q9)+SUMIF('Activities - Construction'!D2:D14,A4,'Activities - Construction'!Q2:Q14)+SUMIF('Activities - Commissioning'!D2:D6,A4,'Activities - Commissioning'!Q2:Q6)) -> 21000 | H4: =IFERROR(F4/(SUMIF('Activities - Engineering'!D2:D9,A4,'Activities - Engineering'!Q2:Q9)+SUMIF('Activities - Procurement'!D2:D9,A4,'Activities - Procurement'!Q2:Q9)+SUMIF('Activities - Construction'!D2:D14,A4,'Activities - Construction'!Q2:Q14)+SUMIF('Activities - Commissioning'!D2:D6,A4,'Activities - Commissioning'!Q2:Q6)),0) -> 1.84
A5: MEP Works | B5: =SUMIFS('Activities - Engineering'!R2:R9,'Activities - Engineering'!D2:D9,A5,'Activities - Engineering'!E2:E9,"P1")+SUMIFS('Activities - Procurement'!R2:R9,'Activities - Procurement'!D2:D9,A5,'Activities - Procurement'!E2:E9,"P1")+SUMIFS('Activities - Construction'!R2:R14,'Activities - Construction'!D2:D14,A5,'Activities - Construction'!E2:E14,"P1")+SUMIFS('Activities - Commissioning'!R2:R6,'Activities - Commissioning'!D2:D6,A5,'Activities - Commissioning'!E2:E6,"P1") -> 0 | C5: =SUMIFS('Activities - Engineering'!R2:R9,'Activities - Engineering'!D2:D9,A5,'Activities - Engineering'!E2:E9,"P2")+SUMIFS('Activities - Procurement'!R2:R9,'Activities - Procurement'!D2:D9,A5,'Activities - Procurement'!E2:E9,"P2")+SUMIFS('Activities - Construction'!R2:R14,'Activities - Construction'!D2:D14,A5,'Activities - Construction'!E2:E14,"P2")+SUMIFS('Activities - Commissioning'!R2:R6,'Activities - Commissioning'!D2:D6,A5,'Activities - Commissioning'!E2:E6,"P2") -> 187500 | D5: =SUMIFS('Activities - Engineering'!R2:R9,'Activities - Engineering'!D2:D9,A5,'Activities - Engineering'!E2:E9,"P3")+SUMIFS('Activities - Procurement'!R2:R9,'Activities - Procurement'!D2:D9,A5,'Activities - Procurement'!E2:E9,"P3")+SUMIFS('Activities - Construction'!R2:R14,'Activities - Construction'!D2:D14,A5,'Activities - Construction'!E2:E14,"P3")+SUMIFS('Activities - Commissioning'!R2:R6,'Activities - Commissioning'!D2:D6,A5,'Activities - Commissioning'!E2:E6,"P3") -> 45000 | E5: =SUMIFS('Activities - Engineering'!R2:R9,'Activities - Engineering'!D2:D9,A5,'Activities - Engineering'!E2:E9,"P4")+SUMIFS('Activities - Procurement'!R2:R9,'Activities - Procurement'!D2:D9,A5,'Activities - Procurement'!E2:E9,"P4")+SUMIFS('Activities - Construction'!R2:R14,'Activities - Construction'!D2:D14,A5,'Activities - Construction'!E2:E14,"P4")+SUMIFS('Activities - Commissioning'!R2:R6,'Activities - Commissioning'!D2:D6,A5,'Activities - Commissioning'!E2:E6,"P4") -> 0 | F5: =SUMIF('Activities - Engineering'!D2:D9,A5,'Activities - Engineering'!S2:S9)+SUMIF('Activities - Procurement'!D2:D9,A5,'Activities - Procurement'!S2:S9)+SUMIF('Activities - Construction'!D2:D14,A5,'Activities - Construction'!S2:S14)+SUMIF('Activities - Commissioning'!D2:D6,A5,'Activities - Commissioning'!S2:S6) -> 335000 | G5: =F5-(SUMIF('Activities - Engineering'!D2:D9,A5,'Activities - Engineering'!Q2:Q9)+SUMIF('Activities - Procurement'!D2:D9,A5,'Activities - Procurement'!Q2:Q9)+SUMIF('Activities - Construction'!D2:D14,A5,'Activities - Construction'!Q2:Q14)+SUMIF('Activities - Commissioning'!D2:D6,A5,'Activities - Commissioning'!Q2:Q6)) -> 5000 | H5: =IFERROR(F5/(SUMIF('Activities - Engineering'!D2:D9,A5,'Activities - Engineering'!Q2:Q9)+SUMIF('Activities - Procurement'!D2:D9,A5,'Activities - Procurement'!Q2:Q9)+SUMIF('Activities - Construction'!D2:D14,A5,'Activities - Construction'!Q2:Q14)+SUMIF('Activities - Commissioning'!D2:D6,A5,'Activities - Commissioning'!Q2:Q6)),0) -> 1.0151515
A6: Labor & Site Overheads | B6: =SUMIFS('Activities - Engineering'!R2:R9,'Activities - Engineering'!D2:D9,A6,'Activities - Engineering'!E2:E9,"P1")+SUMIFS('Activities - Procurement'!R2:R9,'Activities - Procurement'!D2:D9,A6,'Activities - Procurement'!E2:E9,"P1")+SUMIFS('Activities - Construction'!R2:R14,'Activities - Construction'!D2:D14,A6,'Activities - Construction'!E2:E14,"P1")+SUMIFS('Activities - Commissioning'!R2:R6,'Activities - Commissioning'!D2:D6,A6,'Activities - Commissioning'!E2:E6,"P1") -> 0 | C6: =SUMIFS('Activities - Engineering'!R2:R9,'Activities - Engineering'!D2:D9,A6,'Activities - Engineering'!E2:E9,"P2")+SUMIFS('Activities - Procurement'!R2:R9,'Activities - Procurement'!D2:D9,A6,'Activities - Procurement'!E2:E9,"P2")+SUMIFS('Activities - Construction'!R2:R14,'Activities - Construction'!D2:D14,A6,'Activities - Construction'!E2:E14,"P2")+SUMIFS('Activities - Commissioning'!R2:R6,'Activities - Commissioning'!D2:D6,A6,'Activities - Commissioning'!E2:E6,"P2") -> 0 | D6: =SUMIFS('Activities - Engineering'!R2:R9,'Activities - Engineering'!D2:D9,A6,'Activities - Engineering'!E2:E9,"P3")+SUMIFS('Activities - Procurement'!R2:R9,'Activities - Procurement'!D2:D9,A6,'Activities - Procurement'!E2:E9,"P3")+SUMIFS('Activities - Construction'!R2:R14,'Activities - Construction'!D2:D14,A6,'Activities - Construction'!E2:E14,"P3")+SUMIFS('Activities - Commissioning'!R2:R6,'Activities - Commissioning'!D2:D6,A6,'Activities - Commissioning'!E2:E6,"P3") -> 156800 | E6: =SUMIFS('Activities - Engineering'!R2:R9,'Activities - Engineering'!D2:D9,A6,'Activities - Engineering'!E2:E9,"P4")+SUMIFS('Activities - Procurement'!R2:R9,'Activities - Procurement'!D2:D9,A6,'Activities - Procurement'!E2:E9,"P4")+SUMIFS('Activities - Construction'!R2:R14,'Activities - Construction'!D2:D14,A6,'Activities - Construction'!E2:E14,"P4")+SUMIFS('Activities - Commissioning'!R2:R6,'Activities - Commissioning'!D2:D6,A6,'Activities - Commissioning'!E2:E6,"P4") -> 0 | F6: =SUMIF('Activities - Engineering'!D2:D9,A6,'Activities - Engineering'!S2:S9)+SUMIF('Activities - Procurement'!D2:D9,A6,'Activities - Procurement'!S2:S9)+SUMIF('Activities - Construction'!D2:D14,A6,'Activities - Construction'!S2:S14)+SUMIF('Activities - Commissioning'!D2:D6,A6,'Activities - Commissioning'!S2:S6) -> 162000 | G6: =F6-(SUMIF('Activities - Engineering'!D2:D9,A6,'Activities - Engineering'!Q2:Q9)+SUMIF('Activities - Procurement'!D2:D9,A6,'Activities - Procurement'!Q2:Q9)+SUMIF('Activities - Construction'!D2:D14,A6,'Activities - Construction'!Q2:Q14)+SUMIF('Activities - Commissioning'!D2:D6,A6,'Activities - Commissioning'!Q2:Q6)) -> 12000 | H6: =IFERROR(F6/(SUMIF('Activities - Engineering'!D2:D9,A6,'Activities - Engineering'!Q2:Q9)+SUMIF('Activities - Procurement'!D2:D9,A6,'Activities - Procurement'!Q2:Q9)+SUMIF('Activities - Construction'!D2:D14,A6,'Activities - Construction'!Q2:Q14)+SUMIF('Activities - Commissioning'!D2:D6,A6,'Activities - Commissioning'!Q2:Q6)),0) -> 1.08
A7: Engineering & Design Fees | B7: =SUMIFS('Activities - Engineering'!R2:R9,'Activities - Engineering'!D2:D9,A7,'Activities - Engineering'!E2:E9,"P1")+SUMIFS('Activities - Procurement'!R2:R9,'Activities - Procurement'!D2:D9,A7,'Activities - Procurement'!E2:E9,"P1")+SUMIFS('Activities - Construction'!R2:R14,'Activities - Construction'!D2:D14,A7,'Activities - Construction'!E2:E14,"P1")+SUMIFS('Activities - Commissioning'!R2:R6,'Activities - Commissioning'!D2:D6,A7,'Activities - Commissioning'!E2:E6,"P1") -> 82000 | C7: =SUMIFS('Activities - Engineering'!R2:R9,'Activities - Engineering'!D2:D9,A7,'Activities - Engineering'!E2:E9,"P2")+SUMIFS('Activities - Procurement'!R2:R9,'Activities - Procurement'!D2:D9,A7,'Activities - Procurement'!E2:E9,"P2")+SUMIFS('Activities - Construction'!R2:R14,'Activities - Construction'!D2:D14,A7,'Activities - Construction'!E2:E14,"P2")+SUMIFS('Activities - Commissioning'!R2:R6,'Activities - Commissioning'!D2:D6,A7,'Activities - Commissioning'!E2:E6,"P2") -> 96000 | D7: =SUMIFS('Activities - Engineering'!R2:R9,'Activities - Engineering'!D2:D9,A7,'Activities - Engineering'!E2:E9,"P3")+SUMIFS('Activities - Procurement'!R2:R9,'Activities - Procurement'!D2:D9,A7,'Activities - Procurement'!E2:E9,"P3")+SUMIFS('Activities - Construction'!R2:R14,'Activities - Construction'!D2:D14,A7,'Activities - Construction'!E2:E14,"P3")+SUMIFS('Activities - Commissioning'!R2:R6,'Activities - Commissioning'!D2:D6,A7,'Activities - Commissioning'!E2:E6,"P3") -> 0 | E7: =SUMIFS('Activities - Engineering'!R2:R9,'Activities - Engineering'!D2:D9,A7,'Activities - Engineering'!E2:E9,"P4")+SUMIFS('Activities - Procurement'!R2:R9,'Activities - Procurement'!D2:D9,A7,'Activities - Procurement'!E2:E9,"P4")+SUMIFS('Activities - Construction'!R2:R14,'Activities - Construction'!D2:D14,A7,'Activities - Construction'!E2:E14,"P4")+SUMIFS('Activities - Commissioning'!R2:R6,'Activities - Commissioning'!D2:D6,A7,'Activities - Commissioning'!E2:E6,"P4") -> 0 | F7: =SUMIF('Activities - Engineering'!D2:D9,A7,'Activities - Engineering'!S2:S9)+SUMIF('Activities - Procurement'!D2:D9,A7,'Activities - Procurement'!S2:S9)+SUMIF('Activities - Construction'!D2:D14,A7,'Activities - Construction'!S2:S14)+SUMIF('Activities - Commissioning'!D2:D6,A7,'Activities - Commissioning'!S2:S6) -> 178000 | G7: =F7-(SUMIF('Activities - Engineering'!D2:D9,A7,'Activities - Engineering'!Q2:Q9)+SUMIF('Activities - Procurement'!D2:D9,A7,'Activities - Procurement'!Q2:Q9)+SUMIF('Activities - Construction'!D2:D14,A7,'Activities - Construction'!Q2:Q14)+SUMIF('Activities - Commissioning'!D2:D6,A7,'Activities - Commissioning'!Q2:Q6)) -> 3000 | H7: =IFERROR(F7/(SUMIF('Activities - Engineering'!D2:D9,A7,'Activities - Engineering'!Q2:Q9)+SUMIF('Activities - Procurement'!D2:D9,A7,'Activities - Procurement'!Q2:Q9)+SUMIF('Activities - Construction'!D2:D14,A7,'Activities - Construction'!Q2:Q14)+SUMIF('Activities - Commissioning'!D2:D6,A7,'Activities - Commissioning'!Q2:Q6)),0) -> 1.0171429
A8: Contingency Reserve | B8: =SUMIFS('Activities - Engineering'!R2:R9,'Activities - Engineering'!D2:D9,A8,'Activities - Engineering'!E2:E9,"P1")+SUMIFS('Activities - Procurement'!R2:R9,'Activities - Procurement'!D2:D9,A8,'Activities - Procurement'!E2:E9,"P1")+SUMIFS('Activities - Construction'!R2:R14,'Activities - Construction'!D2:D14,A8,'Activities - Construction'!E2:E14,"P1")+SUMIFS('Activities - Commissioning'!R2:R6,'Activities - Commissioning'!D2:D6,A8,'Activities - Commissioning'!E2:E6,"P1") -> 0 | C8: =SUMIFS('Activities - Engineering'!R2:R9,'Activities - Engineering'!D2:D9,A8,'Activities - Engineering'!E2:E9,"P2")+SUMIFS('Activities - Procurement'!R2:R9,'Activities - Procurement'!D2:D9,A8,'Activities - Procurement'!E2:E9,"P2")+SUMIFS('Activities - Construction'!R2:R14,'Activities - Construction'!D2:D14,A8,'Activities - Construction'!E2:E14,"P2")+SUMIFS('Activities - Commissioning'!R2:R6,'Activities - Commissioning'!D2:D6,A8,'Activities - Commissioning'!E2:E6,"P2") -> 0 | D8: =SUMIFS('Activities - Engineering'!R2:R9,'Activities - Engineering'!D2:D9,A8,'Activities - Engineering'!E2:E9,"P3")+SUMIFS('Activities - Procurement'!R2:R9,'Activities - Procurement'!D2:D9,A8,'Activities - Procurement'!E2:E9,"P3")+SUMIFS('Activities - Construction'!R2:R14,'Activities - Construction'!D2:D14,A8,'Activities - Construction'!E2:E14,"P3")+SUMIFS('Activities - Commissioning'!R2:R6,'Activities - Commissioning'!D2:D6,A8,'Activities - Commissioning'!E2:E6,"P3") -> 6300 | E8: =SUMIFS('Activities - Engineering'!R2:R9,'Activities - Engineering'!D2:D9,A8,'Activities - Engineering'!E2:E9,"P4")+SUMIFS('Activities - Procurement'!R2:R9,'Activities - Procurement'!D2:D9,A8,'Activities - Procurement'!E2:E9,"P4")+SUMIFS('Activities - Construction'!R2:R14,'Activities - Construction'!D2:D14,A8,'Activities - Construction'!E2:E14,"P4")+SUMIFS('Activities - Commissioning'!R2:R6,'Activities - Commissioning'!D2:D6,A8,'Activities - Commissioning'!E2:E6,"P4") -> 0 | F8: =SUMIF('Activities - Engineering'!D2:D9,A8,'Activities - Engineering'!S2:S9)+SUMIF('Activities - Procurement'!D2:D9,A8,'Activities - Procurement'!S2:S9)+SUMIF('Activities - Construction'!D2:D14,A8,'Activities - Construction'!S2:S14)+SUMIF('Activities - Commissioning'!D2:D6,A8,'Activities - Commissioning'!S2:S6) -> 12000 | G8: =F8-(SUMIF('Activities - Engineering'!D2:D9,A8,'Activities - Engineering'!Q2:Q9)+SUMIF('Activities - Procurement'!D2:D9,A8,'Activities - Procurement'!Q2:Q9)+SUMIF('Activities - Construction'!D2:D14,A8,'Activities - Construction'!Q2:Q14)+SUMIF('Activities - Commissioning'!D2:D6,A8,'Activities - Commissioning'!Q2:Q6)) -> -38000 | H8: =IFERROR(F8/(SUMIF('Activities - Engineering'!D2:D9,A8,'Activities - Engineering'!Q2:Q9)+SUMIF('Activities - Procurement'!D2:D9,A8,'Activities - Procurement'!Q2:Q9)+SUMIF('Activities - Construction'!D2:D14,A8,'Activities - Construction'!Q2:Q14)+SUMIF('Activities - Commissioning'!D2:D6,A8,'Activities - Commissioning'!Q2:Q6)),0) -> 0.24
A9: Vertical Transportation | B9: =SUMIFS('Activities - Engineering'!R2:R9,'Activities - Engineering'!D2:D9,A9,'Activities - Engineering'!E2:E9,"P1")+SUMIFS('Activities - Procurement'!R2:R9,'Activities - Procurement'!D2:D9,A9,'Activities - Procurement'!E2:E9,"P1")+SUMIFS('Activities - Construction'!R2:R14,'Activities - Construction'!D2:D14,A9,'Activities - Construction'!E2:E14,"P1")+SUMIFS('Activities - Commissioning'!R2:R6,'Activities - Commissioning'!D2:D6,A9,'Activities - Commissioning'!E2:E6,"P1") -> 0 | C9: =SUMIFS('Activities - Engineering'!R2:R9,'Activities - Engineering'!D2:D9,A9,'Activities - Engineering'!E2:E9,"P2")+SUMIFS('Activities - Procurement'!R2:R9,'Activities - Procurement'!D2:D9,A9,'Activities - Procurement'!E2:E9,"P2")+SUMIFS('Activities - Construction'!R2:R14,'Activities - Construction'!D2:D14,A9,'Activities - Construction'!E2:E14,"P2")+SUMIFS('Activities - Commissioning'!R2:R6,'Activities - Commissioning'!D2:D6,A9,'Activities - Commissioning'!E2:E6,"P2") -> 180000 | D9: =SUMIFS('Activities - Engineering'!R2:R9,'Activities - Engineering'!D2:D9,A9,'Activities - Engineering'!E2:E9,"P3")+SUMIFS('Activities - Procurement'!R2:R9,'Activities - Procurement'!D2:D9,A9,'Activities - Procurement'!E2:E9,"P3")+SUMIFS('Activities - Construction'!R2:R14,'Activities - Construction'!D2:D14,A9,'Activities - Construction'!E2:E14,"P3")+SUMIFS('Activities - Commissioning'!R2:R6,'Activities - Commissioning'!D2:D6,A9,'Activities - Commissioning'!E2:E6,"P3") -> 0 | E9: =SUMIFS('Activities - Engineering'!R2:R9,'Activities - Engineering'!D2:D9,A9,'Activities - Engineering'!E2:E9,"P4")+SUMIFS('Activities - Procurement'!R2:R9,'Activities - Procurement'!D2:D9,A9,'Activities - Procurement'!E2:E9,"P4")+SUMIFS('Activities - Construction'!R2:R14,'Activities - Construction'!D2:D14,A9,'Activities - Construction'!E2:E14,"P4")+SUMIFS('Activities - Commissioning'!R2:R6,'Activities - Commissioning'!D2:D6,A9,'Activities - Commissioning'!E2:E6,"P4") -> 0 | F9: =SUMIF('Activities - Engineering'!D2:D9,A9,'Activities - Engineering'!S2:S9)+SUMIF('Activities - Procurement'!D2:D9,A9,'Activities - Procurement'!S2:S9)+SUMIF('Activities - Construction'!D2:D14,A9,'Activities - Construction'!S2:S14)+SUMIF('Activities - Commissioning'!D2:D6,A9,'Activities - Commissioning'!S2:S6) -> 225000 | G9: =F9-(SUMIF('Activities - Engineering'!D2:D9,A9,'Activities - Engineering'!Q2:Q9)+SUMIF('Activities - Procurement'!D2:D9,A9,'Activities - Procurement'!Q2:Q9)+SUMIF('Activities - Construction'!D2:D14,A9,'Activities - Construction'!Q2:Q14)+SUMIF('Activities - Commissioning'!D2:D6,A9,'Activities - Commissioning'!Q2:Q6)) -> 5000 | H9: =IFERROR(F9/(SUMIF('Activities - Engineering'!D2:D9,A9,'Activities - Engineering'!Q2:Q9)+SUMIF('Activities - Procurement'!D2:D9,A9,'Activities - Procurement'!Q2:Q9)+SUMIF('Activities - Construction'!D2:D14,A9,'Activities - Construction'!Q2:Q14)+SUMIF('Activities - Commissioning'!D2:D6,A9,'Activities - Commissioning'!Q2:Q6)),0) -> 1.0227273
A10: Facade & Glazing | B10: =SUMIFS('Activities - Engineering'!R2:R9,'Activities - Engineering'!D2:D9,A10,'Activities - Engineering'!E2:E9,"P1")+SUMIFS('Activities - Procurement'!R2:R9,'Activities - Procurement'!D2:D9,A10,'Activities - Procurement'!E2:E9,"P1")+SUMIFS('Activities - Construction'!R2:R14,'Activities - Construction'!D2:D14,A10,'Activities - Construction'!E2:E14,"P1")+SUMIFS('Activities - Commissioning'!R2:R6,'Activities - Commissioning'!D2:D6,A10,'Activities - Commissioning'!E2:E6,"P1") -> 0 | C10: =SUMIFS('Activities - Engineering'!R2:R9,'Activities - Engineering'!D2:D9,A10,'Activities - Engineering'!E2:E9,"P2")+SUMIFS('Activities - Procurement'!R2:R9,'Activities - Procurement'!D2:D9,A10,'Activities - Procurement'!E2:E9,"P2")+SUMIFS('Activities - Construction'!R2:R14,'Activities - Construction'!D2:D14,A10,'Activities - Construction'!E2:E14,"P2")+SUMIFS('Activities - Commissioning'!R2:R6,'Activities - Commissioning'!D2:D6,A10,'Activities - Commissioning'!E2:E6,"P2") -> 0 | D10: =SUMIFS('Activities - Engineering'!R2:R9,'Activities - Engineering'!D2:D9,A10,'Activities - Engineering'!E2:E9,"P3")+SUMIFS('Activities - Procurement'!R2:R9,'Activities - Procurement'!D2:D9,A10,'Activities - Procurement'!E2:E9,"P3")+SUMIFS('Activities - Construction'!R2:R14,'Activities - Construction'!D2:D14,A10,'Activities - Construction'!E2:E14,"P3")+SUMIFS('Activities - Commissioning'!R2:R6,'Activities - Commissioning'!D2:D6,A10,'Activities - Commissioning'!E2:E6,"P3") -> 155000 | E10: =SUMIFS('Activities - Engineering'!R2:R9,'Activities - Engineering'!D2:D9,A10,'Activities - Engineering'!E2:E9,"P4")+SUMIFS('Activities - Procurement'!R2:R9,'Activities - Procurement'!D2:D9,A10,'Activities - Procurement'!E2:E9,"P4")+SUMIFS('Activities - Construction'!R2:R14,'Activities - Construction'!D2:D14,A10,'Activities - Construction'!E2:E14,"P4")+SUMIFS('Activities - Commissioning'!R2:R6,'Activities - Commissioning'!D2:D6,A10,'Activities - Commissioning'!E2:E6,"P4") -> 0 | F10: =SUMIF('Activities - Engineering'!D2:D9,A10,'Activities - Engineering'!S2:S9)+SUMIF('Activities - Procurement'!D2:D9,A10,'Activities - Procurement'!S2:S9)+SUMIF('Activities - Construction'!D2:D14,A10,'Activities - Construction'!S2:S14)+SUMIF('Activities - Commissioning'!D2:D6,A10,'Activities - Commissioning'!S2:S6) -> 460000 | G10: =F10-(SUMIF('Activities - Engineering'!D2:D9,A10,'Activities - Engineering'!Q2:Q9)+SUMIF('Activities - Procurement'!D2:D9,A10,'Activities - Procurement'!Q2:Q9)+SUMIF('Activities - Construction'!D2:D14,A10,'Activities - Construction'!Q2:Q14)+SUMIF('Activities - Commissioning'!D2:D6,A10,'Activities - Commissioning'!Q2:Q6)) -> 20000 | H10: =IFERROR(F10/(SUMIF('Activities - Engineering'!D2:D9,A10,'Activities - Engineering'!Q2:Q9)+SUMIF('Activities - Procurement'!D2:D9,A10,'Activities - Procurement'!Q2:Q9)+SUMIF('Activities - Construction'!D2:D14,A10,'Activities - Construction'!Q2:Q14)+SUMIF('Activities - Commissioning'!D2:D6,A10,'Activities - Commissioning'!Q2:Q6)),0) -> 1.0454545
A11: Fit-Out & Finishes | B11: =SUMIFS('Activities - Engineering'!R2:R9,'Activities - Engineering'!D2:D9,A11,'Activities - Engineering'!E2:E9,"P1")+SUMIFS('Activities - Procurement'!R2:R9,'Activities - Procurement'!D2:D9,A11,'Activities - Procurement'!E2:E9,"P1")+SUMIFS('Activities - Construction'!R2:R14,'Activities - Construction'!D2:D14,A11,'Activities - Construction'!E2:E14,"P1")+SUMIFS('Activities - Commissioning'!R2:R6,'Activities - Commissioning'!D2:D6,A11,'Activities - Commissioning'!E2:E6,"P1") -> 0 | C11: =SUMIFS('Activities - Engineering'!R2:R9,'Activities - Engineering'!D2:D9,A11,'Activities - Engineering'!E2:E9,"P2")+SUMIFS('Activities - Procurement'!R2:R9,'Activities - Procurement'!D2:D9,A11,'Activities - Procurement'!E2:E9,"P2")+SUMIFS('Activities - Construction'!R2:R14,'Activities - Construction'!D2:D14,A11,'Activities - Construction'!E2:E14,"P2")+SUMIFS('Activities - Commissioning'!R2:R6,'Activities - Commissioning'!D2:D6,A11,'Activities - Commissioning'!E2:E6,"P2") -> 0 | D11: =SUMIFS('Activities - Engineering'!R2:R9,'Activities - Engineering'!D2:D9,A11,'Activities - Engineering'!E2:E9,"P3")+SUMIFS('Activities - Procurement'!R2:R9,'Activities - Procurement'!D2:D9,A11,'Activities - Procurement'!E2:E9,"P3")+SUMIFS('Activities - Construction'!R2:R14,'Activities - Construction'!D2:D14,A11,'Activities - Construction'!E2:E14,"P3")+SUMIFS('Activities - Commissioning'!R2:R6,'Activities - Commissioning'!D2:D6,A11,'Activities - Commissioning'!E2:E6,"P3") -> 58000 | E11: =SUMIFS('Activities - Engineering'!R2:R9,'Activities - Engineering'!D2:D9,A11,'Activities - Engineering'!E2:E9,"P4")+SUMIFS('Activities - Procurement'!R2:R9,'Activities - Procurement'!D2:D9,A11,'Activities - Procurement'!E2:E9,"P4")+SUMIFS('Activities - Construction'!R2:R14,'Activities - Construction'!D2:D14,A11,'Activities - Construction'!E2:E14,"P4")+SUMIFS('Activities - Commissioning'!R2:R6,'Activities - Commissioning'!D2:D6,A11,'Activities - Commissioning'!E2:E6,"P4") -> 0 | F11: =SUMIF('Activities - Engineering'!D2:D9,A11,'Activities - Engineering'!S2:S9)+SUMIF('Activities - Procurement'!D2:D9,A11,'Activities - Procurement'!S2:S9)+SUMIF('Activities - Construction'!D2:D14,A11,'Activities - Construction'!S2:S14)+SUMIF('Activities - Commissioning'!D2:D6,A11,'Activities - Commissioning'!S2:S6) -> 168000 | G11: =F11-(SUMIF('Activities - Engineering'!D2:D9,A11,'Activities - Engineering'!Q2:Q9)+SUMIF('Activities - Procurement'!D2:D9,A11,'Activities - Procurement'!Q2:Q9)+SUMIF('Activities - Construction'!D2:D14,A11,'Activities - Construction'!Q2:Q14)+SUMIF('Activities - Commissioning'!D2:D6,A11,'Activities - Commissioning'!Q2:Q6)) -> 3000 | H11: =IFERROR(F11/(SUMIF('Activities - Engineering'!D2:D9,A11,'Activities - Engineering'!Q2:Q9)+SUMIF('Activities - Procurement'!D2:D9,A11,'Activities - Procurement'!Q2:Q9)+SUMIF('Activities - Construction'!D2:D14,A11,'Activities - Construction'!Q2:Q14)+SUMIF('Activities - Commissioning'!D2:D6,A11,'Activities - Commissioning'!Q2:Q6)),0) -> 1.0181818
